<?xml version="1.0"?>
<robot xmlns:xacro="http://www.ros.org/wiki/xacro" name="robot">
    <!-- =================================================================================== -->
    <!-- |                                     Wheels                                      | -->
    <!-- =================================================================================== -->

    <!-- Left Front Wheel Joint!-->
    <joint name="left_front_wheel_joint" type="continuous">
        <parent link="base_link" />
        <child link="left_front_wheel" />
        <origin xyz="0.0575 0.0640 0.035" rpy="${-pi/2} 0.0 0.0" />
        <axis xyz="0 0 1" />
    </joint>

    <!-- Left Front Wheel !-->
    <link name="left_front_wheel">
        <visual>
            <geometry>
                <cylinder radius="0.035" length="0.025" />
            </geometry>
            <origin xyz="0.0 0.0 0.0" rpy="0 0 0" />
            <material name="BlackWheel" />
        </visual>
        <collision>
            <geometry>
                <!-- <cylinder radius="0.0325" length="0.026" /> -->
                <sphere radius="0.0325" />
            </geometry>
        </collision>
        <xacro:inertial_cylinder mass="0.027" length="0.025" radius="0.035">
            <origin xyz="0.0 0.0 0.0" rpy="0 0 0" />
        </xacro:inertial_cylinder>
    </link>

    <!-- Right Front Wheel Joint!-->
    <joint name="right_front_wheel_joint" type="continuous">
        <parent link="base_link" />
        <child link="right_front_wheel" />
        <origin xyz="0.0575 -0.0640 0.035" rpy="${pi/2} 0.0 0.0" />
        <axis xyz="0 0 -1" />
    </joint>

    <!-- Right Front Wheel !-->
    <link name="right_front_wheel">
        <visual>
            <geometry>
                <cylinder radius="0.035" length="0.025" />
            </geometry>
            <origin xyz="0.0 0.0 0.0" rpy="0 0 0" />
            <material name="BlackWheel" />
        </visual>
        <collision>
            <geometry>
                <!-- <cylinder radius="0.0325" length="0.026" /> -->
                <sphere radius="0.0325" />
            </geometry>
        </collision>
        <xacro:inertial_cylinder mass="0.027" length="0.025" radius="0.035">
            <origin xyz="0.0 0.0 0.0" rpy="0 0 0" />
        </xacro:inertial_cylinder>
    </link>

    <!-- Left Rear Wheel Joint!-->
    <joint name="left_rear_wheel_joint" type="continuous">
        <parent link="base_link" />
        <child link="left_rear_wheel" />
        <origin xyz="-0.0575 0.0640 0.035" rpy="-${pi/2} 0.0 0.0" />
        <axis xyz="0 0 1" />
    </joint>

    <!-- Left Rear Wheel !-->
    <link name="left_rear_wheel">
        <visual>
            <geometry>
                <cylinder radius="0.035" length="0.025" />
            </geometry>
            <origin xyz="0.0 0.0 0.0" rpy="0 0 0" />
            <material name="BlackWheel" />
        </visual>
        <collision>
            <geometry>
                <!-- <cylinder radius="0.0325" length="0.026" /> -->
                <sphere radius="0.0325" />
            </geometry>
        </collision>
        <xacro:inertial_cylinder mass="0.027" length="0.025" radius="0.035">
            <origin xyz="0.0 0.0 0.0" rpy="0 0 0" />
        </xacro:inertial_cylinder>
    </link>

    <!-- Right Rear Wheel Joint!-->
    <joint name="right_rear_wheel_joint" type="continuous">
        <parent link="base_link" />
        <child link="right_rear_wheel" />
        <origin xyz="-0.0575 -0.0640 0.035" rpy="${pi/2} 0.0 0.0" />
        <axis xyz="0 0 -1" />
    </joint>

    <!-- Right Rear Wheel !-->
    <link name="right_rear_wheel">
        <visual>
            <geometry>
                <cylinder radius="0.035" length="0.025" />
            </geometry>
            <origin xyz="0.0 0.0 0.0" rpy="0 0 0" />
            <material name="BlackWheel" />
        </visual>
        <collision>
            <geometry>
                <!-- <cylinder radius="0.0325" length="0.026" /> -->
                <sphere radius="0.0325" />
            </geometry>
        </collision>
        <xacro:inertial_cylinder mass="0.027" length="0.025" radius="0.035">
            <origin xyz="0.0 0.0 0.0" rpy="0 0 0" />
        </xacro:inertial_cylinder>
    </link>
    

</robot>